<?xml version="1.0"?>
<robot name="craig2">

    <link name="base_link">
        <visual>
            <origin xyz="0 0 0.15" rpy="0 0 0"/>
            <geometry>
                <box size="0.1 0.12 0.3"/>
            </geometry>
            <material name="orange">
                <color rgba="1.0 0.5 0.0 1"/>
            </material>
        </visual>
        <collision>
            <origin xyz="0 0 0.15" rpy="0 0 0"/>
            <geometry>
                <box size="0.1 0.12 0.3"/>
            </geometry>
        </collision>
        <inertial>
            <origin xyz="0 0 0.15" rpy="0 0 0"/>
            <mass value="1.0"/>
            <inertia ixx="0.0087" ixy="0.0" ixz="0.0" iyy="0.0083" iyz="0.0" izz="0.002"/>
        </inertial>
    </link>

    <link name="left_wheel">
        <visual>
            <origin xyz="0 0 0" rpy="1.5708 0 0"/>
            <geometry><cylinder radius="0.05" length="0.04"/></geometry>
            <material name="black"><color rgba="0.1 0.1 0.1 1.0"/></material>
        </visual>
        <collision>
            <origin xyz="0 0 0" rpy="1.5708 0 0"/>
            <geometry><cylinder radius="0.05" length="0.04"/></geometry>
        </collision>
        <inertial>
            <origin xyz="0 0 0" rpy="0 0 0"/>
            <mass value="0.1"/>
            <inertia ixx="0.00008" ixy="0.0" ixz="0.0" iyy="0.00008" iyz="0.0" izz="0.00013"/>
        </inertial>
    </link>
    <joint name="left_wheel_joint" type="continuous">
        <parent link="base_link"/>
        <child link="left_wheel"/>
        <origin xyz="0 0.07 0" rpy="0 0 0"/>
        <axis xyz="0 1 0"/>
    </joint>

    <link name="right_wheel">
        <visual>
            <origin xyz="0 0 0" rpy="1.5708 0 0"/>
            <geometry><cylinder radius="0.05" length="0.04"/></geometry>
            <material name="black"><color rgba="0.1 0.1 0.1 1.0"/></material>
        </visual>
        <collision>
            <origin xyz="0 0 0" rpy="1.5708 0 0"/>
            <geometry><cylinder radius="0.05" length="0.04"/></geometry>
        </collision>
        <inertial>
            <origin xyz="0 0 0" rpy="0 0 0"/>
            <mass value="0.1"/>
            <inertia ixx="0.00008" ixy="0.0" ixz="0.0" iyy="0.00008" iyz="0.0" izz="0.00013"/>
        </inertial>
    </link>
    <joint name="right_wheel_joint" type="continuous">
        <parent link="base_link"/>
        <child link="right_wheel"/>
        <origin xyz="0 -0.07 0" rpy="0 0 0"/>
        <axis xyz="0 1 0"/>
    </joint>



    <link name="imu_link">
        <visual>
            <geometry><box size="0.02 0.02 0.005"/></geometry>
        </visual>
        <inertial>
            <mass value="0.01"/>
            <inertia ixx="1e-6" ixy="0.0" ixz="0.0" iyy="1e-6" iyz="0.0" izz="1e-6"/>
        </inertial>
    </link>
    <joint name="imu_joint" type="fixed">
        <parent link="base_link"/>
        <child link="imu_link"/>
        <origin xyz="0 0 0.1" rpy="0 0 0"/>
    </joint>
    <gazebo>
        <plugin filename="gz-sim-diff-drive-system" name="gz::sim::systems::DiffDrive">
            <left_joint>left_wheel_joint</left_joint>
            <right_joint>right_wheel_joint</right_joint>
            <wheel_separation>0.14</wheel_separation>
            <wheel_radius>0.05</wheel_radius>
            <topic>cmd_vel</topic>
            <odom_topic>odom</odom_topic>
            <frame_id>odom</frame_id>
            <child_frame_id>base_link</child_frame_id>
            <tf_topic>tf</tf_topic>
        </plugin> 
    </gazebo>
    <gazebo reference="imu_link">
        <sensor name="imu" type="imu">
            <topic>imu</topic>
            <update_rate>100</update_rate>
            <always_on>true</always_on>
            <gz_frame_id>imu_link</gz_frame_id>
        </sensor>
    </gazebo>
</robot>