<?xml version="1.0"?>
<robot name="craig">
 <link name="base_link">
  <visual>
    <geometry>
     <box size="0.3 0.2 0.1"/>
    </geometry>
    <material name="blue">
        <color rgba="0.2 0.2 0.8 1.0"/>
    </material>
  </visual>
  <collision>
      <geometry>
        <box size="0.3 0.2 0.1"/>
      </geometry>
  </collision>
  <inertial>
      <mass value="1.0"/>
      <inertia ixx="0.0042" ixy="0.0" ixz="0.0" iyy="0.0083" iyz="0.0" izz="0.0108"/>
  </inertial>
 </link>
 
  <link name="left_wheel">
     <visual>
       <origin xyz="0 0 0" rpy="1.5708 0 0"/>
       <geometry>
         <cylinder radius="0.05" length="0.04"/>
       </geometry>
       <material name="black">
            <color rgba="0.1 0.1 0.1 1.0"/>
       </material>
     </visual>
     <collision>
      <origin xyz="0 0 0" rpy="1.5708 0 0"/>
      <geometry>
        <cylinder radius="0.05" length="0.04"/>
      </geometry>
    </collision>
    <inertial>
      <origin xyz="0 0 0" rpy="1.5708 0 0"/>
      <mass value="0.1"/>
      <inertia ixx="0.00008" ixy="0.0" ixz="0.0" iyy="0.00008" iyz="0.0" izz="0.00013"/>
    </inertial>
  </link>

   <joint name="left_wheel_joint" type="continuous">
     <parent link="base_link"/>
     <child link="left_wheel"/>
     <origin xyz="-0.03 0.12 -0.03" rpy="0 0 0"/>
     <axis xyz="0 1 0"/>
   </joint>

  <link name="right_wheel">
      <visual>
        <origin xyz="0 0 0" rpy="1.5708 0 0"/>
        <geometry>
          <cylinder radius="0.05" length="0.04"/>
        </geometry>
        <material name="black">
             <color rgba="0.1 0.1 0.1 1.0"/>
        </material>
      </visual>
      <collision>
       <origin xyz="0 0 0" rpy="1.5708 0 0"/>
       <geometry>
         <cylinder radius="0.05" length="0.04"/>
       </geometry>
     </collision>
     <inertial>
       <origin xyz="0 0 0" rpy="1.5708 0 0"/>
       <mass value="0.1"/>
       <inertia ixx="0.00008" ixy="0.0" ixz="0.0" iyy="0.00008" iyz="0.0" izz="0.00013"/>
     </inertial>
    </link>

    <joint name="right_wheel_joint" type="continuous">
     <parent link="base_link"/>
     <child link="right_wheel"/>
     <origin xyz="-0.03 -0.12 -0.03" rpy="0 0 0"/>
     <axis xyz="0 1 0"/>
    </joint>

  <link name="caster">
    <visual>
      <geometry>
        <sphere radius="0.03"/>
      </geometry>
      <material name="red">
            <color rgba="1.0 0.1 0.1 1.0"/>
      </material>
    </visual>
    <collision>
      <geometry>
        <sphere radius="0.03"/>
      </geometry>
    </collision>
    <inertial>
      <mass value="0.05"/>
      <inertia ixx="0.00002" ixy="0.0" ixz="0.0" iyy="0.00002" iyz="0.0" izz="0.00002"/>
    </inertial>
  </link>

  <joint name="caster_joint" type="fixed">
    <parent link="base_link"/>
    <child link="caster"/>
    <origin xyz="0.12 0 -0.05" rpy="0 0 0"/>
  </joint>

  <gazebo>
    <plugin filename="gz-sim-diff-drive-system" name="gz::sim::systems::DiffDrive">
      <left_joint>left_wheel_joint</left_joint>
      <right_joint>right_wheel_joint</right_joint>
      <wheel_separation>0.24</wheel_separation>
      <wheel_radius>0.05</wheel_radius>
      <topic>cmd_vel</topic>
      <odom_topic>odom</odom_topic>
      <frame_id>odom</frame_id>
      <child_frame_id>base_link</child_frame_id>
    </plugin>
  </gazebo>

  <link name="lidar_link">
    <visual>
      <geometry>
        <cylinder radius="0.035" length="0.02"/>
      </geometry>
      <material name="black">
        <color rgba="0.1 0.1 0.1 1.0"/>
      </material>
    </visual>
    <collision>
      <geometry>
        <cylinder radius="0.035" length="0.02"/>
      </geometry>
    </collision>
    <inertial>
      <mass value="0.05"/>
      <inertia ixx="0.00002" ixy="0.0" ixz="0.0" iyy="0.00002" iyz="0.0" izz="0.00003"/>
    </inertial>
  </link>

  <joint name="lidar_joint" type="fixed">
    <parent link="base_link"/>
    <child link="lidar_link"/>
    <origin xyz="0 0 0.06" rpy="0 0 0"/>
  </joint>

  <gazebo reference="lidar_link">
    <sensor name="lidar" type="gpu_lidar">
      <topic>scan</topic>
      <update_rate>10</update_rate>
      <gz_frame_id>lidar_link</gz_frame_id>
      <ray>
        <scan>
          <horizontal>
            <samples>360</samples>
            <resolution>1</resolution>
            <min_angle>-3.14159</min_angle>
            <max_angle>3.14159</max_angle>
          </horizontal>
        </scan>
        <range>
          <min>0.12</min>
          <max>12.0</max>
        </range>
      </ray>
      <always_on>1</always_on>
      <visualize>true</visualize>
    </sensor>
  </gazebo>

</robot>
