<?xml version="1.0"?>
<robot name="craig">
 <link name="base_link">
  <visual>
    <geometry>
     <box size="0.3 0.2 0.1"/>
    </geometry>
    <material name="blue">
        <color rgba="0.2 0.2 0.8 1.0"/>
    </material>
  </visual>
 </link>
 
 <link name="left_wheel">
     <visual>
       <origin xyz="0 0 0" rpy="1.5708 0 0"/>
       <geometry>
         <cylinder radius="0.05" length="0.04"/>
       </geometry>
       <material name="black">
            <color rgba="0.1 0.1 0.1 1.0"/>
       </material>
     </visual>
   </link>

   <joint name="left_wheel_joint" type="continuous">
     <parent link="base_link"/>
     <child link="left_wheel"/>
     <origin xyz="-0.03 0.12 -0.03" rpy="0 0 0"/>
     <axis xyz="0 1 0"/>
   </joint>

 <link name="right_wheel">
     <visual>
       <origin xyz="0 0 0" rpy="1.5708 0 0"/>
       <geometry>
         <cylinder radius="0.05" length="0.04"/>
       </geometry>
       <material name="black">
            <color rgba="0.1 0.1 0.1 1.0"/>
       </material>
     </visual>
   </link>

   <joint name="right_wheel_joint" type="continuous">
     <parent link="base_link"/>
     <child link="right_wheel"/>
     <origin xyz="-0.03 -0.12 -0.03" rpy="0 0 0"/>
     <axis xyz="0 1 0"/>
   </joint>

  <link name="caster">
    <visual>
      <geometry>
        <sphere radius="0.03"/>
      </geometry>
      <material name="red">
            <color rgba="1.0 0.1 0.1 1.0"/>
      </material>
    </visual>
  </link>

  <joint name="caster_joint" type="fixed">
    <parent link="base_link"/>
    <child link="caster"/>
    <origin xyz="0.12 0 -0.05" rpy="0 0 0"/>
  </joint>
</robot>
